<mujoco model="4bar">
    <compiler coordinate="local" />
    <option timestep="0.005" />
    <default>
        <geom rgba="0.0 0.4 0.6 1" contype='0' conaffinity='1'/>
        <equality solref='0.005 1'/>
    </default>

    <option gravity="1e-5 0 -9.81" integrator="RK4" timestep="0.01"/>

    <asset>
        <texture type='skybox' builtin='gradient' width='128' height='128' rgb1='0.4 0.6 0.8' rgb2='0 0 0'/>
        <texture name="texplane" type="2d" builtin="checker" rgb1=".4 .4 .4" rgb2=".6 .6 .6" 
            width="512" height="512"/>  
    </asset>

    <worldbody>
        <light directional="true" diffuse=".8 .8 .8" pos="0 0 10" dir="0 0 -10"/>

        <!-- Chain 1 -->
        <body name="body00" pos="0 0 0">
            <geom fromto="0 0 0 0 0 0.15" name="link0" size=".01" type="capsule"/>
            <joint axis="0 1 0" name="joint0" pos="0 0 0" type="hinge" damping="0.01"/>
            <!-- <joint name="joint0r" type="ball" />
            <joint axis="1 0 0" name="joint0x" pos="0 0 0" type="slide"/>
            <joint axis="0 1 0" name="joint0y" pos="0 0 0" type="slide"/>
            <joint axis="0 0 1" name="joint0z" pos="0 0 0" type="slide"/> -->
            <!-- <joint type="free" /> -->

            <body name="body01" pos="0 0 0.15">
                <!-- 0 0 0 -> 0.2in(pi/4) 0 0.2cos(pi/4) -->
                <geom fromto="0 0 0 0.1414 0 0.1414" name="link1"  size=".01"  type="capsule"/>
                <joint axis="0 1 0" name="joint1" pos="0 0 0" type="hinge"/>

                <body name="end0" pos="0.1414 0 0.1414">
                </body>
            </body>

            <!-- Chain 2 -->
            <body name="body10" pos="0 0 0">
                <!-- 0 0 0 -> 0.06sin(pi/4) 0 0.06cos(pi/4) -->
                <geom fromto="0 0 0 0.04242 0 0.04242" name="link2" size=".01" type="capsule"/>
                <joint axis="0 1 0" name="joint2" pos="0 0 0" type="hinge"/>

                <body name="body11" pos="0.04242 0 0.04242">
                    <geom fromto="0 0 0 0 0 0.15" name="link3"  size=".01"  type="capsule"/>
                    <joint axis="0 1 0" name="joint3" pos="0 0 0" type="hinge"/>

                    <body name="end1" pos="0 0 0.15">
                    </body>
                </body>
            </body>
        </body>

    </worldbody>

    <equality>
        <connect body1="end1" body2="body01" anchor="0 0 0"/>
    </equality>
</mujoco>